Workbook

Sheet NZTL
A1: Sl No | B1: PI NO | C1: Applicant Name | D1: Issuing Bank | E1: LC Number | F1: LC Date | G1: LC Rev Date | H1: LC Value | I1: Amd Value | J1: Total Value | K1: Unit Price | L1: Quantity | M1: Shipment Date | N1: Expiry Date | O1: Marketing Person
A2: =A3+1 -> 767 | B2: 23241/26 | C2: NZ DENIM LTD. | D2: SHAHJALAL ISLAMI BANK LTD. KAWRAN BAZAR BRANCH | E2: 2970 2603 00068 | F2: 24.06.26 | G2: 46198 | H2: 82335 | J2: =SUM(Table1[[#This Row],[LC Value]:[Amd Value]]) -> 82335 | K2: 3.3 | L2: 24950 | M2: 20.08.26 | N2: 10.09.26 | O2: =IFERROR(_xlfn.XLOOKUP(C2, Data!$A$2:$A$236, Data!$C$2:$C$236), "") -> MD. Sir
A3: =A4+1 -> 766 | B3: 23242/26 | C3: NZ DENIM LTD. | D3: SHAHJALAL ISLAMI BANK LTD. KAWRAN BAZAR BRANCH | E3: 2970 2603 00069 | F3: 24.06.26 | G3: 46198 | H3: 32400 | J3: =SUM(Table1[[#This Row],[LC Value]:[Amd Value]]) -> 32400 | K3: 3.6 | L3: 9000 | M3: 20.08.26 | N3: 10.09.26 | O3: =IFERROR(_xlfn.XLOOKUP(C3, Data!$A$2:$A$236, Data!$C$2:$C$236), "") -> MD. Sir
A4: =A5+1 -> 765 | B4: 23238/26 | C4: NZ FABRICS LTD. | D4: BRAC BANK T.O. TEJGAON BRANCH. | E4: 3085 2603 00965 | F4: 24.06.26 | G4: 46198 | H4: 27840 | J4: =SUM(Table1[[#This Row],[LC Value]:[Amd Value]]) -> 27840 | K4: 3.35 | L4: 8700 | M4: 20.08.26 | N4: 10.09.26 | O4: =IFERROR(_xlfn.XLOOKUP(C4, Data!$A$2:$A$236, Data!$C$2:$C$236), "") -> MD. Sir
A5: =A6+1 -> 764 | B5: 23215/26 23216/26 23217/26 23219/26 | C5: NZ FABRICS LTD. | D5: EBL TRADE OPERATIONS GULSHAN BRANCH. | E5: 1475 2603 01607 | F5: 24.06.26 | G5: 46198 | H5: =71297.5+86262.5+112357.5+28382.5 -> 298300 | J5: =SUM(Table1[[#This Row],[LC Value]:[Amd Value]]) -> 298300 | K5: 3.35 | L5: 27850 | M5: 20.08.26 | N5: 10.09.26 | O5: =IFERROR(_xlfn.XLOOKUP(C5, Data!$A$2:$A$236, Data!$C$2:$C$236), "") -> MD. Sir
A6: =A7+1 -> 763 | B6: 23218/26 | C6: NZ FABRICS LTD. | D6: CITY BANK PLC TSD. GULSHAN BRANCH. | E6: 0751 2603 01002 | F6: 24.06.26 | G6: 46198 | H6: 65722.5 | J6: =SUM(Table1[[#This Row],[LC Value]:[Amd Value]]) -> 65722.5 | K6: 3.45 | L6: 19050 | M6: 20.08.26 | N6: 10.09.26 | O6: =IFERROR(_xlfn.XLOOKUP(C6, Data!$A$2:$A$236, Data!$C$2:$C$236), "") -> MD. Sir
A7: =A8+1 -> 762 | B7: 23239/26 | C7: NZ DENIM LTD. | D7: CITY BANK PLC TSD. GULSHAN BRANCH. | E7: 0751 2603 01007 | F7: 24.06.26 | G7: 46198 | H7: 139612.5 | J7: =SUM(Table1[[#This Row],[LC Value]:[Amd Value]]) -> 139612.5 | K7: 2.95 | L7: 46850 | M7: 20.08.26 | N7: 10.09.26 | O7: =IFERROR(_xlfn.XLOOKUP(C7, Data!$A$2:$A$236, Data!$C$2:$C$236), "") -> MD. Sir
A8: =A9+1 -> 761 | B8: 231768/26 | C8: SONNET TEXTILE INDUSTRIES LTD. | D8: PREMIER BANK PLC AGRABAD BRANCH | E8: 2151 2604 00119 | F8: 23.06.26 | G8: 46197 | H8: 35900 | J8: =SUM(Table1[[#This Row],[LC Value]:[Amd Value]]) -> 35900 | K8: 3.45 | L8: 10000 | M8: 20.08.26 | N8: 10.09.26 | O8: =IFERROR(_xlfn.XLOOKUP(C8, Data!$A$2:$A$236, Data!$C$2:$C$236), "") -> Mr. Lipu Sir
A9: =A10+1 -> 760 | B9: 23201/26 | C9: RIPON KNITWEAR LTD. | D9: SOUTHEAST BANK PLC. GULSHAN BRANCH | E9: 1343 2603 00372 | F9: 23.06.26 | G9: 46197 | H9: 22580 | J9: =SUM(Table1[[#This Row],[LC Value]:[Amd Value]]) -> 22580 | K9: 4.1 | L9: 5450 | M9: 25.07.26 | N9: 09.08.26 | O9: =IFERROR(_xlfn.XLOOKUP(C9, Data!$A$2:$A$236, Data!$C$2:$C$236), "") -> Mr. Reza Sir
A10: =A11+1 -> 759 | B10: 23224/26 | C10: NZ FABRICS LTD. | D10: EBL TRADE OPERATIONS GULSHAN BRANCH. | E10: 1475 2603 01584 | F10: 23.06.26 | G10: 46197 | H10: 8917.5 | J10: =SUM(Table1[[#This Row],[LC Value]:[Amd Value]]) -> 8917.5 | K10: 2.5 | L10: 2600 | M10: 25.07.26 | N10: 09.08.26 | O10: =IFERROR(_xlfn.XLOOKUP(C10, Data!$A$2:$A$236, Data!$C$2:$C$236), "") -> MD. Sir
A11: =A12+1 -> 758 | B11: 23227/26 | C11: NZ DENIM LTD. | D11: CITY BANK PLC TSD. GULSHAN BRANCH. | E11: 0751 2603 00998 | F11: 23.06.26 | G11: 46197 | H11: 35750 | J11: =SUM(Table1[[#This Row],[LC Value]:[Amd Value]]) -> 35750 | K11: 2.5 | L11: 14300 | M11: 25.07.26 | N11: 09.08.26 | O11: =IFERROR(_xlfn.XLOOKUP(C11, Data!$A$2:$A$236, Data!$C$2:$C$236), "") -> MD. Sir
A12: =A13+1 -> 757 | B12: 23085/26 | C12: SCANDEX TEXTILE INDUSTRIES LTD. | D12: UCBL NARAYANGANJ BRANCH | E12: 1009 2604 00430 | F12: 22.06.26 | G12: 53250 | H12: 53250 | J12: =SUM(Table1[[#This Row],[LC Value]:[Amd Value]]) -> 53250 | K12: 3.55 | L12: 15000 | M12: 25.07.26 | N12: 09.08.26 | O12: =IFERROR(_xlfn.XLOOKUP(C12, Data!$A$2:$A$236, Data!$C$2:$C$236), "") -> Mr. Reza Sir
A13: =A14+1 -> 756 | B13: 23197/26 | C13: NZ FABRICS LTD. | D13: CITY BANK PLC TSD. GULSHAN BRANCH. | E13: 0751 2603 00984 | F13: 22.06.26 | G13: 46196 | H13: 16920 | J13: =SUM(Table1[[#This Row],[LC Value]:[Amd Value]]) -> 16920 | K13: 3.6 | L13: 4700 | M13: 30.07.26 | N13: 14.08.26 | O13: =IFERROR(_xlfn.XLOOKUP(C13, Data!$A$2:$A$236, Data!$C$2:$C$236), "") -> MD. Sir
A14: =A15+1 -> 755 | B14: 23196/26 | C14: NZ FABRICS LTD. | D14: CITY BANK PLC TSD. GULSHAN BRANCH. | E14: 0751 2603 00986 | F14: 22.06.26 | G14: 46196 | H14: 11470 | J14: =SUM(Table1[[#This Row],[LC Value]:[Amd Value]]) -> 11470 | K14: 3.7 | L14: 3100 | M14: 30.07.26 | N14: 14.08.26 | O14: =IFERROR(_xlfn.XLOOKUP(C14, Data!$A$2:$A$236, Data!$C$2:$C$236), "") -> MD. Sir
A15: =A16+1 -> 754 | B15: 23209/26 | C15: IMPRESS NEWTEX COMPOSITE TEXTILES LTD. | D15: ONE BANK PLC BANANI BRANCH | E15: 1886 2603 00128 | F15: 22.06.26 | G15: 46195 | H15: 63014.5 | J15: =SUM(Table1[[#This Row],[LC Value]:[Amd Value]]) -> 63014.5 | K15: 3.93 | L15: 17400 | M15: 10.07.26 | N15: 25.07.26 | O15: =IFERROR(_xlfn.XLOOKUP(C15, Data!$A$2:$A$236, Data!$C$2:$C$236), "") -> Mr. Reza Sir
A16: =A17+1 -> 753 | B16: 23220/26 | C16: Tex Fabrics | D16: UTTARA BANK PLC FOREIGN EXCHANGE BRANCH | E16: 0435 2604 0530 | F16: 22.06.26 | G16: 46195 | H16: 10500 | J16: =SUM(Table1[[#This Row],[LC Value]:[Amd Value]]) -> 10500 | K16: 3.4 | L16: 3000 | M16: 10.07.26 | N16: 25.07.26 | O16: =IFERROR(_xlfn.XLOOKUP(C16, Data!$A$2:$A$236, Data!$C$2:$C$236), "") -> Mr. Lipu Sir
A17: =A18+1 -> 752 | B17: 23207/26 | C17: IMPRESS NEWTEX COMPOSITE TEXTILES LTD. | D17: ONE BANK PLC BANANI BRANCH | E17: 1886 2603 00127 | F17: 22.06.26 | G17: 46195 | H17: 27144 | J17: =SUM(Table1[[#This Row],[LC Value]:[Amd Value]]) -> 27144 | K17: 3.48 | L17: 7800 | M17: 20.07.26 | N17: 30.07.26 | O17: =IFERROR(_xlfn.XLOOKUP(C17, Data!$A$2:$A$236, Data!$C$2:$C$236), "") -> Mr. Reza Sir
A18: =A19+1 -> 751 | B18: 23200/26 | C18: ASTRO KNITWEAR LTD. | D18: SOUTHEAST BANK LTD. CORPORATE BRANCH | E18: 1351 2604 01000 | F18: 21.06.26 | G18: 46195 | H18: 141900 | J18: =SUM(Table1[[#This Row],[LC Value]:[Amd Value]]) -> 141900 | K18: 4.25 | L18: 24500 | M18: 25.07.26 | N18: 10.08.26 | O18: =IFERROR(_xlfn.XLOOKUP(C18, Data!$A$2:$A$236, Data!$C$2:$C$236), "") -> Mr. Reza Sir
A19: =A20+1 -> 750 | B19: 23167/26 | C19: COTTON CLOUT (BD) LTD. | D19: PUBALI BANK PLC. MOHAKHALI BRANCH | E19: 0216 2604 01724 | F19: 21.06.26 | G19: 46195 | H19: =104125+62250 -> 166375 | J19: =SUM(Table1[[#This Row],[LC Value]:[Amd Value]]) -> 166375 | K19: 4.25 | L19: 24500 | M19: 01.08.26 | N19: 11.08.26 | O19: =IFERROR(_xlfn.XLOOKUP(C19, Data!$A$2:$A$236, Data!$C$2:$C$236), "") -> Director Sir
A20: =A21+1 -> 749 | B20: 23203/26 | C20: NZ FABRICS LTD. | D20: EBL TRADE OPERATIONS GULSHAN BRANCH. | E20: 1475 2603 01562 | F20: 21.06.26 | G20: 46195 | H20: 56625 | J20: =SUM(Table1[[#This Row],[LC Value]:[Amd Value]]) -> 56625 | K20: 3.75 | L20: 15100 | M20: 30.07.26 | N20: 15.08.26 | O20: =IFERROR(_xlfn.XLOOKUP(C20, Data!$A$2:$A$236, Data!$C$2:$C$236), "") -> MD. Sir
A21: =A22+1 -> 748 | B21: 23204/26 | C21: NZ FABRICS LTD. | D21: EBL TRADE OPERATIONS GULSHAN BRANCH. | E21: 1475 2603 01563 | F21: 21.06.26 | G21: 46195 | H21: 17430 | J21: =SUM(Table1[[#This Row],[LC Value]:[Amd Value]]) -> 17430 | K21: 4.2 | L21: 17430 | M21: 30.07.26 | N21: 15.08.26 | O21: =IFERROR(_xlfn.XLOOKUP(C21, Data!$A$2:$A$236, Data!$C$2:$C$236), "") -> MD. Sir
A22: =A23+1 -> 747 | B22: 23202/26 | C22: NZ FABRICS LTD. | D22: EBL TRADE OPERATIONS GULSHAN BRANCH. | E22: 1475 2603 01564 | F22: 21.06.26 | G22: 46197 | H22: 18450 | J22: =SUM(Table1[[#This Row],[LC Value]:[Amd Value]]) -> 18450 | K22: 3 | L22: 6150 | M22: 30.07.26 | N22: 15.08.26 | O22: =IFERROR(_xlfn.XLOOKUP(C22, Data!$A$2:$A$236, Data!$C$2:$C$236), "") -> MD. Sir
A23: =A24+1 -> 746 | B23: 23097/26 | C23: ESQUIRE KNIT COMPOSITE LTD. | D23: AL-ARAFAH ISLAMI BANK PLC GULSHAN BRANCH | E23: 1086 2604 01400 | F23: 21.06.26 | G23: 46195 | H23: 34597.5 | J23: =SUM(Table1[[#This Row],[LC Value]:[Amd Value]]) -> 34597.5 | K23: 3.8 | L23: 9200 | M23: 30.07.26 | N23: 15.08.26 | O23: =IFERROR(_xlfn.XLOOKUP(C23, Data!$A$2:$A$236, Data!$C$2:$C$236), "") -> Mr. Sohel Sir
A24: =A25+1 -> 745 | B24: 23150/26 | C24: COTTON CLUB (BD) LTD. | D24: UCBL UTTARA BRANCH | E24: 1021 2604 01026 | F24: 16.06.26 | G24: 46197 | H24: 18850 | J24: =SUM(Table1[[#This Row],[LC Value]:[Amd Value]]) -> 18850 | K24: 3.45 | L24: 5000 | M24: 30.11.26 | N24: 15.12.26 | O24: =IFERROR(_xlfn.XLOOKUP(C24, Data!$A$2:$A$236, Data!$C$2:$C$236), "") -> Director Sir
A25: =A26+1 -> 744 | B25: 23194/26 | C25: NZ DENIM LTD. | D25: BRAC BANK T.O. TEJGAON BRANCH. | E25: 3085 2603 00927 | F25: 18.06.26 | G25: 46193 | H25: 31455 | J25: =SUM(Table1[[#This Row],[LC Value]:[Amd Value]]) -> 31455 | K25: 2.7 | L25: 11650 | M25: 30.11.26 | N25: 15.12.26 | O25: =IFERROR(_xlfn.XLOOKUP(C25, Data!$A$2:$A$236, Data!$C$2:$C$236), "") -> MD. Sir
A26: =A27+1 -> 743 | B26: 23155/26 | C26: S M KNITWEARS LTD. | D26: EBL TRADE OPERATIONS GULSHAN BRANCH. | E26: 1475 2604 06465 | F26: 18.06.26 | G26: 46197 | H26: 14255 | J26: =SUM(Table1[[#This Row],[LC Value]:[Amd Value]]) -> 14255 | K26: 3.65 | L26: 3900 | M26: 30.11.26 | N26: 15.12.26 | O26: =IFERROR(_xlfn.XLOOKUP(C26, Data!$A$2:$A$236, Data!$C$2:$C$236), "") -> Mr. Reza Sir
A27: =A28+1 -> 742 | B27: 23179/26 | C27: AR TEX COMPOSITE LTD. | D27: DBBL NARAYANGANJ BRANCH | E27: 1680 2604 01066 | F27: 18.06.26 | G27: 46193 | H27: 91250 | J27: =SUM(Table1[[#This Row],[LC Value]:[Amd Value]]) -> 91250 | K27: 3.65 | L27: 25000 | M27: 30.11.26 | N27: 15.12.26 | O27: =IFERROR(_xlfn.XLOOKUP(C27, Data!$A$2:$A$236, Data!$C$2:$C$236), "") -> Mr. Sohel Sir
A28: =A29+1 -> 741 | B28: 23193/26 | C28: NZ FABRICS LTD. | D28: EBL TO GULSHAN AVENUE | E28: 1475 2603 01546 | F28: 18.06.26 | G28: 46197 | H28: 15900 | J28: =SUM(Table1[[#This Row],[LC Value]:[Amd Value]]) -> 15900 | K28: 3.6 | L28: 3950 | M28: 30.11.26 | N28: 15.12.26 | O28: =IFERROR(_xlfn.XLOOKUP(C28, Data!$A$2:$A$236, Data!$C$2:$C$236), "") -> MD. Sir
A29: =A30+1 -> 740 | B29: 23192/26 | C29: NZ FABRICS LTD. | D29: EBL TO GULSHAN AVENUE | E29: 1475 2603 01545 | F29: 18.06.26 | G29: 46197 | H29: 20502.5 | J29: =SUM(Table1[[#This Row],[LC Value]:[Amd Value]]) -> 20502.5 | K29: 4.4 | L29: 29350 | M29: 30.11.26 | N29: 15.12.26 | O29: =IFERROR(_xlfn.XLOOKUP(C29, Data!$A$2:$A$236, Data!$C$2:$C$236), "") -> MD. Sir
A30: =A31+1 -> 739 | B30: 23195/26 | C30: NZ DENIM LTD. | D30: CITY BANK PLC TSD. GULSHAN BRANCH. | E30: 0751 2604 05801 | F30: 18.06.26 | G30: 46196 | H30: 84700 | J30: =SUM(Table1[[#This Row],[LC Value]:[Amd Value]]) -> 84700 | K30: 4.4 | L30: 29350 | M30: 30.11.26 | N30: 15.12.26 | O30: =IFERROR(_xlfn.XLOOKUP(C30, Data!$A$2:$A$236, Data!$C$2:$C$236), "") -> MD. Sir
A31: =A32+1 -> 738 | B31: 23182/26 | C31: NZ FABRICS LTD. | D31: CITY BANK PLC TSD. GULSHAN BRANCH. | E31: 0751 2603 00966 | F31: 18.06.26 | G31: 46193 | H31: 8460 | J31: =SUM(Table1[[#This Row],[LC Value]:[Amd Value]]) -> 8460 | K31: 4.4 | L31: 1950 | M31: 30.11.26 | N31: 15.12.26 | O31: =IFERROR(_xlfn.XLOOKUP(C31, Data!$A$2:$A$236, Data!$C$2:$C$236), "") -> MD. Sir
... A35: =A36+1 -> 734 | B35: 23135/26 | C35: MODELE DE CAPITAL IND. LTD. | D35: PUBALI BANK N.GONJ BRANCH. | E35: 0202 2604 01786 | F35: 14.06.26 | G35: 46191 | H35: 111880 | J35: =SUM(Table1[[#This Row],[LC Value]:[Amd Value]]) -> 111880 | K35: 3.4 | L35: 32800 | M35: 30.11.26 | N35: 15.12.26 | O35: =IFERROR(_xlfn.XLOOKUP(C35, Data!$A$2:$A$236, Data!$C$2:$C$236), "") -> Director Sir
A36: =A37+1 -> 733 | B36: 23177/26 | C36: SCARLET KNITWEAR'S LTD. | D36: SHAHJALAL ISLAMI BANK LTD. NARAYANGANJ BRANCH | E36: 2971 2604 01890 | F36: 46196 | G36: 46190 | H36: 12150 | J36: =SUM(Table1[[#This Row],[LC Value]:[Amd Value]]) -> 12150 | K36: 4.05 | L36: 3000 | M36: 15.07.26 | N36: 30.07.26 | O36: =IFERROR(_xlfn.XLOOKUP(C36, Data!$A$2:$A$236, Data!$C$2:$C$236), "") -> Mr. Amran Sir
A37: =A38+1 -> 732 | B37: 23171/26 | C37: NZ DENIM LTD. | D37: SHAHJALAL ISLAMI BANK LTD. KAWRAN BAZAR BRANCH | E37: 2970 2603 00067 | F37: 16.06.26 | G37: 46195 | H37: 82765 | J37: =SUM(Table1[[#This Row],[LC Value]:[Amd Value]]) -> 82765 | K37: 3.5 | L37: 24200 | M37: 14.07.26 | N37: 29.07.26 | O37: =IFERROR(_xlfn.XLOOKUP(C37, Data!$A$2:$A$236, Data!$C$2:$C$236), "") -> MD. Sir
A38: =A39+1 -> 731 | B38: 23170/26 | C38: NZ DENIM LTD. | D38: BRAC BANK T.O. TEJGAON BRANCH. | E38: 3085 2603 00913 | F38: 16.06.26 | G38: 46195 | H38: 15937.5 | J38: =SUM(Table1[[#This Row],[LC Value]:[Amd Value]]) -> 15937.5 | K38: 3.5 | L38: 6250 | M38: 14.07.26 | N38: 29.07.26 | O38: =IFERROR(_xlfn.XLOOKUP(C38, Data!$A$2:$A$236, Data!$C$2:$C$236), "") -> MD. Sir
A39: =A40+1 -> 730 | B39: 23172/26 | C39: NZ DENIM LTD. | D39: BRAC BANK T.O. TEJGAON BRANCH. | E39: 3085 2603 00918 | F39: 16.06.26 | G39: 46195 | H39: 65340 | J39: =SUM(Table1[[#This Row],[LC Value]:[Amd Value]]) -> 65340 | K39: 3.5 | L39: 18150 | M39: 14.07.26 | N39: 29.07.26 | O39: =IFERROR(_xlfn.XLOOKUP(C39, Data!$A$2:$A$236, Data!$C$2:$C$236), "") -> MD. Sir
A40: =A41+1 -> 729 | B40: 23173/26 | C40: NZ DENIM LTD. | D40: BRAC BANK T.O. TEJGAON BRANCH. | E40: 3085 2604 05153 | F40: 16.06.26 | G40: 46196 | H40: 108150 | J40: =SUM(Table1[[#This Row],[LC Value]:[Amd Value]]) -> 108150 | K40: 3.5 | L40: 30900 | M40: 14.07.26 | N40: 29.07.26 | O40: =IFERROR(_xlfn.XLOOKUP(C40, Data!$A$2:$A$236, Data!$C$2:$C$236), "") -> MD. Sir
A41: =A42+1 -> 728 | B41: 23166/26 | C41: NZ DENIM LTD. | D41: CITY BANK PLC TSD. GULSHAN BRANCH. | E41: 0751 2603 00954 | F41: 16.06.26 | G41: 46197 | H41: 60187.5 | J41: =SUM(Table1[[#This Row],[LC Value]:[Amd Value]]) -> 60187.5 | K41: 2.75 | L41: 21650 | M41: 14.07.26 | N41: 29.07.26 | O41: =IFERROR(_xlfn.XLOOKUP(C41, Data!$A$2:$A$236, Data!$C$2:$C$236), "") -> MD. Sir
A42: =A43+1 -> 727 | B42: 23160/26 | C42: NZ FABRICS LTD. | D42: CITY BANK PLC TSD. GULSHAN BRANCH. | E42: 0751 2603 00956 | F42: 16.06.26 | G42: 46197 | H42: 30780 | J42: =SUM(Table1[[#This Row],[LC Value]:[Amd Value]]) -> 30780 | K42: 3.6 | L42: 8550 | M42: 14.07.26 | N42: 29.07.26 | O42: =IFERROR(_xlfn.XLOOKUP(C42, Data!$A$2:$A$236, Data!$C$2:$C$236), "") -> MD. Sir
A43: =A44+1 -> 726 | B43: 23163/26 | C43: NZ FABRICS LTD. | D43: BRAC BANK T.O. TEJGAON BRANCH. | E43: 3085 2603 00912 | F43: 16.06.26 | G43: 46195 | H43: 29040 | J43: =SUM(Table1[[#This Row],[LC Value]:[Amd Value]]) -> 29040 | K43: 4.8 | L43: 6050 | M43: 14.07.26 | N43: 29.07.26 | O43: =IFERROR(_xlfn.XLOOKUP(C43, Data!$A$2:$A$236, Data!$C$2:$C$236), "") -> MD. Sir
...

Sheet NZAL
A1: Sl No | B1: PI NO | C1: Applicant Name | D1: Issuing Bank | E1: LC Number | F1: LC Date | G1: LC Rev Date | H1: LC Value | I1: Amd Value | J1: Total | K1: Unit Price | L1: Quantity | M1: Shipment Date | N1: Expiry Date | O1: Marketing Person
A2: =A3+1 -> 220 | B2: 21228/26 | C2: NZ DENIM LTD. | D2: SHAHJALAL ISLAMI BANK LTD. KAWRAN BAZAR BRANCH | E2: 2970 2603 00070 | F2: 24.06.26 | G2: 46198 | H2: 83070 | J2: =SUM(Table14[[#This Row],[LC Value]:[Amd Value]]) -> 83070 | K2: 2.8 | L2: 28700 | M2: 10.08.26 | N2: 25.08.26 | O2: =IFERROR(_xlfn.XLOOKUP(C2, Data!$A$2:$A$236, Data!$C$2:$C$236), "") -> MD. Sir
A3: =A4+1 -> 219 | B3: 211225/26 | C3: NZ DENIM LTD. | D3: SHAHJALAL ISLAMI BANK LTD. KAWRAN BAZAR BRANCH | E3: 2970 2603 00071 | F3: 24.06.26 | G3: 46198 | H3: 14420 | J3: =SUM(Table14[[#This Row],[LC Value]:[Amd Value]]) -> 14420 | K3: 2.8 | L3: 5150 | M3: 10.08.26 | N3: 25.08.26 | O3: =IFERROR(_xlfn.XLOOKUP(C3, Data!$A$2:$A$236, Data!$C$2:$C$236), "") -> MD. Sir
A4: =A5+1 -> 218 | B4: 21218/26 21219/26 21220/26 21221/26 | C4: NZ FABRICS LTD. | D4: CITY BANK PLC TSD. GULSHAN BRANCH. | E4: 0751 2603 01001 | F4: 24.06.26 | G4: 46198 | H4: =33740+58007.5+15600+126315 -> 233662.5 | J4: =SUM(Table14[[#This Row],[LC Value]:[Amd Value]]) -> 233662.5 | K4: 2.8 | L4: =12050+24700+6500+35650 -> 78900 | M4: 10.08.26 | N4: 25.08.26 | O4: =IFERROR(_xlfn.XLOOKUP(C4, Data!$A$2:$A$236, Data!$C$2:$C$236), "") -> MD. Sir
A5: =A6+1 -> 217 | B5: 21215/26 | C5: NZ DENIM LTD. | D5: BRAC BANK T.O. TEJGAON BRANCH. | E5: 3085 2603 00965 | F5: 18.06.26 | G5: 46197 | H5: 56197.5 | J5: =SUM(Table14[[#This Row],[LC Value]:[Amd Value]]) -> 56197.5 | K5: 2.95 | L5: 19050 | M5: 09.07.26 | N5: 24.07.26 | O5: =IFERROR(_xlfn.XLOOKUP(C5, Data!$A$2:$A$236, Data!$C$2:$C$236), "") -> MD. Sir
A6: =A7+1 -> 216 | B6: 21204/26 | C6: NZ DENIM LTD. | D6: BRAC BANK T.O. TEJGAON BRANCH. | E6: 3085 2603 00922 | F6: 18.06.26 | G6: 46197 | H6: 15365 | J6: =SUM(Table14[[#This Row],[LC Value]:[Amd Value]]) -> 15365 | K6: 3.9 | L6: 3900 | M6: 09.07.26 | N6: 24.07.26 | O6: =IFERROR(_xlfn.XLOOKUP(C6, Data!$A$2:$A$236, Data!$C$2:$C$236), "") -> MD. Sir
A7: =A8+1 -> 215 | B7: 21212/26 | C7: NZ DENIM LTD. | D7: BRAC BANK T.O. TEJGAON BRANCH. | E7: 3085 2603 00917 | F7: 17.06.26 | G7: 46195 | H7: 178777.5 | J7: =SUM(Table14[[#This Row],[LC Value]:[Amd Value]]) -> 178777.5 | K7: 3.35 | L7: 54450 | M7: 01.08.26 | N7: 16.08.26 | O7: =IFERROR(_xlfn.XLOOKUP(C7, Data!$A$2:$A$236, Data!$C$2:$C$236), "") -> MD. Sir
A8: =A9+1 -> 214 | B8: 21197/26 | C8: OSMAN GARMENTS LTD. | D8: AL-ARAFAH ISLAMI BANK LTD. N.GANJ BRANCH | E8: 1088 2604 00658 | F8: 17.06.26 | G8: 46197 | H8: 44800 | J8: =SUM(Table14[[#This Row],[LC Value]:[Amd Value]]) -> 44800 | K8: 3.2 | L8: 14000 | M8: 01.08.26 | N8: 16.08.26 | O8: =IFERROR(_xlfn.XLOOKUP(C8, Data!$A$2:$A$236, Data!$C$2:$C$236), "") -> Mr. Shahbuddin
A9: =A10+1 -> 213 | B9: 21198/26 | C9: OSMAN GARMENTS LTD. | D9: AL-ARAFAH ISLAMI BANK LTD. N.GANJ BRANCH | E9: 1088 2604 00654 | F9: 16.06.26 | G9: 46195 | H9: 44800 | J9: =SUM(Table14[[#This Row],[LC Value]:[Amd Value]]) -> 44800 | K9: 3.2 | L9: 14000 | M9: 01.08.26 | N9: 16.08.26 | O9: =IFERROR(_xlfn.XLOOKUP(C9, Data!$A$2:$A$236, Data!$C$2:$C$236), "") -> Mr. Shahbuddin
A10: =A11+1 -> 212 | B10: 21202/26 | C10: OSMAN GARMENTS LTD. | D10: AL-ARAFAH ISLAMI BANK LTD. N.GANJ BRANCH | E10: 1088 2604 00655 | F10: 16.06.26 | G10: 46195 | H10: 9600 | J10: =SUM(Table14[[#This Row],[LC Value]:[Amd Value]]) -> 9600 | K10: 3.2 | L10: 3000 | M10: 01.08.26 | N10: 16.08.26 | O10: =IFERROR(_xlfn.XLOOKUP(C10, Data!$A$2:$A$236, Data!$C$2:$C$236), "") -> Mr. Shahbuddin
A11: =A12+1 -> 211 | B11: 21203/26 | C11: NZ FABRICS LTD. | D11: CITY BANK PLC TSD. GULSHAN BRANCH. | E11: 0751 2603 00955 | F11: 16.06.26 | G11: 46196 | H11: 61782.5 | J11: =SUM(Table14[[#This Row],[LC Value]:[Amd Value]]) -> 61782.5 | K11: 3.1 | L11: 18250 | M11: 31.07.26 | N11: 15.08.26 | O11: =IFERROR(_xlfn.XLOOKUP(C11, Data!$A$2:$A$236, Data!$C$2:$C$236), "") -> MD. Sir
A12: =A13+1 -> 210 | B12: 21205/26 | C12: NZ DENIM LTD. | D12: CITY BANK PLC TSD. GULSHAN BRANCH. | E12: 0751 2603 00953 | F12: 16.06.26 | G12: 46196 | H12: 20000 | J12: =SUM(Table14[[#This Row],[LC Value]:[Amd Value]]) -> 20000 | K12: 2.5 | L12: 8000 | M12: 31.07.26 | N12: 15.08.26 | O12: =IFERROR(_xlfn.XLOOKUP(C12, Data!$A$2:$A$236, Data!$C$2:$C$236), "") -> MD. Sir
A13: =A14+1 -> 209 | B13: 21207/26 | C13: NZ DENIM LTD. | D13: SHAHJALAL ISLAMI BANK LTD. KAWRAN BAZAR BRANCH | E13: 2970 2603 00066 | F13: 16.06.26 | G13: 46195 | H13: 47840 | J13: =SUM(Table14[[#This Row],[LC Value]:[Amd Value]]) -> 47840 | K13: 3.2 | L13: 14950 | M13: 31.07.26 | N13: 15.08.26 | O13: =IFERROR(_xlfn.XLOOKUP(C13, Data!$A$2:$A$236, Data!$C$2:$C$236), "") -> MD. Sir
A14: =A15+1 -> 208 | B14: 21193/26 | C14: NZ FABRICS LTD. | D14: CITY BANK PLC TSD. GULSHAN BRANCH. | E14: 0751 2603 00947 | F14: 14.06.26 | G14: 46191 | H14: 11935 | J14: =SUM(Table14[[#This Row],[LC Value]:[Amd Value]]) -> 11935 | K14: 3.85 | L14: 3100 | M14: 31.07.26 | N14: 15.08.26 | O14: =IFERROR(_xlfn.XLOOKUP(C14, Data!$A$2:$A$236, Data!$C$2:$C$236), "") -> MD. Sir
A15: =A16+1 -> 207 | B15: 21179/26 | C15: M.M. KNITWEAR LTD. | D15: UCBL BANGSHAL BRANCH | E15: 1007 2604 01461 | F15: 10.06.26 | G15: 46189 | H15: 28050 | J15: =SUM(Table14[[#This Row],[LC Value]:[Amd Value]]) -> 28050 | K15: 3.3 | L15: 8500 | M15: 31.07.26 | N15: 15.08.26 | O15: =IFERROR(_xlfn.XLOOKUP(C15, Data!$A$2:$A$236, Data!$C$2:$C$236), "") -> Mr. Reza Sir
A16: =A17+1 -> 206 | B16: 21186/26 | C16: M.M. KNITWEAR LTD. | D16: UCBL BANGSHAL BRANCH | E16: 1007 2604 01449 | F16: 10.06.26 | G16: 46189 | H16: 82500 | J16: =SUM(Table14[[#This Row],[LC Value]:[Amd Value]]) -> 82500 | K16: 3.3 | L16: 25500 | M16: 31.07.26 | N16: 15.08.26 | O16: =IFERROR(_xlfn.XLOOKUP(C16, Data!$A$2:$A$236, Data!$C$2:$C$236), "") -> Mr. Reza Sir
... A31: =A32+1 -> 191 | B31: 21189/26 | C31: MAMUN KNITWEAR LTD. | D31: UCBL BANGSHAL BRANCH | E31: 1007 2604 01430 | F31: 10.06.26 | G31: 46189 | H31: 71000 | J31: =SUM(Table14[[#This Row],[LC Value]:[Amd Value]]) -> 71000 | K31: 3.55 | L31: 20000 | M31: 31.07.26 | N31: 15.08.26 | O31: =IFERROR(_xlfn.XLOOKUP(C31, Data!$A$2:$A$236, Data!$C$2:$C$236), "") -> Mr. Reza Sir
A32: =A33+1 -> 190 | B32: 21159/26 21160/26 | C32: NZ DENIM LTD. | D32: BRAC BANK T.O. TEJGAON BRANCH. | E32: 3085 2603 00830 | F32: 24.05.26 | G32: 46184 | H32: =62530+108405 -> 170935 | J32: =SUM(Table14[[#This Row],[LC Value]:[Amd Value]]) -> 170935 | K32: 3.7 | L32: 3750 | M32: 14.07.26 | N32: 29.07.26 | O32: =IFERROR(_xlfn.XLOOKUP(C32, Data!$A$2:$A$236, Data!$C$2:$C$236), "") -> MD. Sir
A33: =A34+1 -> 189 | B33: 21188/26 | C33: NZ FABRICS LTD. | D33: CITY BANK PLC TSD. GULSHAN BRANCH. | E33: 0751 2603 00925 | F33: 07.06.26 | G33: 46183 | H33: 17930 | J33: =SUM(Table14[[#This Row],[LC Value]:[Amd Value]]) -> 17930 | K33: 4.75 | L33: 3750 | M33: 14.07.26 | N33: 29.07.26 | O33: =IFERROR(_xlfn.XLOOKUP(C33, Data!$A$2:$A$236, Data!$C$2:$C$236), "") -> MD. Sir
A34: =A35+1 -> 188 | B34: 21163/26 | C34: KAIZER KNITWEARS LTD. | D34: SOUTHEAST BANK LTD. NEW ESKATON BRANCH | E34: 1347 2604 00643 | F34: 24.05.26 | G34: 46177 | H34: =320000+320000 -> 640000 | J34: =SUM(Table14[[#This Row],[LC Value]:[Amd Value]]) -> 640000 | K34: 3.2 | L34: 200000 | M34: 30.06.26 | N34: 10.07.26 | O34: =IFERROR(_xlfn.XLOOKUP(C34, Data!$A$2:$A$236, Data!$C$2:$C$236), "") -> Director Sir
A35: =A36+1 -> 187 | B35: 21171/26 | C35: NZ FABRICS LTD. | D35: CITY BANK PLC TSD. GULSHAN BRANCH. | E35: 0751 2603 00920 | F35: 03.06.26 | G35: 46181 | H35: 20685 | J35: =SUM(Table14[[#This Row],[LC Value]:[Amd Value]]) -> 20685 | K35: 3.35 | L35: 5200 | M35: 20.07.26 | N35: 10.08.26 | O35: =IFERROR(_xlfn.XLOOKUP(C35, Data!$A$2:$A$236, Data!$C$2:$C$236), "") -> MD. Sir
A36: =A37+1 -> 186 | B36: 21150/26 | C36: PACIFIC KNITEX LTD. | D36: HSBC TEJGAON BRANCH | E36: DCBD1182018 | F36: 20.05.26 | G36: 46176 | H36: 73700 | J36: =SUM(Table14[[#This Row],[LC Value]:[Amd Value]]) -> 73700 | K36: 3.35 | L36: 22000 | M36: 20.07.26 | N36: 10.08.26 | O36: =IFERROR(_xlfn.XLOOKUP(C36, Data!$A$2:$A$236, Data!$C$2:$C$236), "") -> MD. Sir
A37: =A38+1 -> 185 | B37: 21165/26 | C37: NZ FABRICS LTD. | D37: BRAC BANK T.O. TEJGAON BRANCH. | E37: 3085 2603 00832 | F37: 02.06.26 | G37: 46181 | H37: 9627 | J37: =SUM(Table14[[#This Row],[LC Value]:[Amd Value]]) -> 9627 | K37: 3.3 | L37: 1100 | M37: 20.07.26 | N37: 04.08.26 | O37: =IFERROR(_xlfn.XLOOKUP(C37, Data!$A$2:$A$236, Data!$C$2:$C$236), "") -> MD. Sir
A38: =A39+1 -> 184 | B38: 21162/26 | C38: NZ FABRICS LTD. | D38: BRAC BANK T.O. TEJGAON BRANCH. | E38: 3085 2603 00828 | F38: 23.05.26 | G38: 46181 | H38: 5445 | J38: =SUM(Table14[[#This Row],[LC Value]:[Amd Value]]) -> 5445 | K38: 3.3 | L38: 1100 | M38: 20.07.26 | N38: 04.08.26 | O38: =IFERROR(_xlfn.XLOOKUP(C38, Data!$A$2:$A$236, Data!$C$2:$C$236), "") -> MD. Sir
A39: =A40+1 -> 183 | B39: 21152/26 | C39: NZ FABRICS LTD. | D39: EBL TO GULSHAN AVENUE | E39: 1475 2603 01365 | F39: 23.05.26 | G39: 46177 | H39: 290565 | J39: =SUM(Table14[[#This Row],[LC Value]:[Amd Value]]) -> 290565 | K39: 3.3 | L39: 88050 | M39: 20.07.26 | N39: 04.08.26 | O39: =IFERROR(_xlfn.XLOOKUP(C39, Data!$A$2:$A$236, Data!$C$2:$C$236), "") -> MD. Sir
A40: =A41+1 -> 182 | B40: 21147/26 | C40: MAMUN KNITWEAR LTD. | D40: UCBL BANGSHAL BRANCH | E40: 1007 2604 01371 | F40: 21.05.26 | G40: 46176 | H40: 60800 | J40: =SUM(Table14[[#This Row],[LC Value]:[Amd Value]]) -> 60800 | K40: 3.8 | L40: 16000 | M40: 15.07.26 | N40: 30.07.26 | O40: =IFERROR(_xlfn.XLOOKUP(C40, Data!$A$2:$A$236, Data!$C$2:$C$236), "") -> Mr. Reza Sir
A41: =A42+1 -> 181 | B41: 21137/26 | C41: NZ FABRICS LTD. | D41: CITY BANK PLC TSD. GULSHAN BRANCH. | E41: 0751 2603 00867 | F41: 46161 | G41: 46176 | H41: 28250 | J41: =SUM(Table14[[#This Row],[LC Value]:[Amd Value]]) -> 28250 | K41: 3.05 | L41: 9000 | M41: 05.07.26 | N41: 20.07.26 | O41: =IFERROR(_xlfn.XLOOKUP(C41, Data!$A$2:$A$236, Data!$C$2:$C$236), "") -> MD. Sir
A42: =A43+1 -> 180 | B42: 21153/26 | C42: NZ FABRICS LTD. | D42: BRAC BANK T.O. TEJGAON BRANCH. | E42: 3085 2603 00783 | F42: 46161 | G42: 46176 | H42: 26482.5 | J42: =SUM(Table14[[#This Row],[LC Value]:[Amd Value]]) -> 26482.5 | K42: 2.4 | L42: 5350 | M42: 05.07.26 | N42: 20.07.26 | O42: =IFERROR(_xlfn.XLOOKUP(C42, Data!$A$2:$A$236, Data!$C$2:$C$236), "") -> MD. Sir
A43: =A44+1 -> 179 | B43: 21155/26 | C43: NZ DENIM LTD. | D43: BRAC BANK T.O. TEJGAON BRANCH. | E43: 3085 2603 00785 | F43: 46161 | G43: 46176 | H43: 44105 | J43: =SUM(Table14[[#This Row],[LC Value]:[Amd Value]]) -> 44105 | K43: 2.4 | L43: 18150 | M43: 05.07.26 | N43: 20.07.26 | O43: =IFERROR(_xlfn.XLOOKUP(C43, Data!$A$2:$A$236, Data!$C$2:$C$236), "") -> MD. Sir
A44: =A45+1 -> 178 | B44: 21146/26 | C44: NZ DENIM LTD. | D44: BRAC BANK T.O. TEJGAON BRANCH. | E44: 3085 2603 00772 | F44: 17.05.26 | G44: 46176 | H44: 38440 | J44: =SUM(Table14[[#This Row],[LC Value]:[Amd Value]]) -> 38440 | K44: 3.1 | L44: 12400 | M44: 15.06.26 | N44: 30.06.26 | O44: =IFERROR(_xlfn.XLOOKUP(C44, Data!$A$2:$A$236, Data!$C$2:$C$236), "") -> MD. Sir
A45: =A46+1 -> 177 | B45: 21135/26 | C45: MAMUN KNITWEAR LTD. | D45: UCBL BANGSHAL BRANCH | E45: 1007 2604 01271 | F45: 14.05.26 | G45: 46162 | H45: 37000 | J45: =SUM(Table14[[#This Row],[LC Value]:[Amd Value]]) -> 37000 | K45: 3.7 | L45: 10000 | M45: 15.06.26 | N45: 30.06.26 | O45: =IFERROR(_xlfn.XLOOKUP(C45, Data!$A$2:$A$236, Data!$C$2:$C$236), "") -> Mr. Reza Sir
A46: =A47+1 -> 176 | B46: 21134/26 | C46: MAMUN KNITWEAR LTD. | D46: UCBL BANGSHAL BRANCH | E46: 1007 2604 01274 | F46: 14.05.26 | G46: 46158 | H46: 66600 | J46: =SUM(Table14[[#This Row],[LC Value]:[Amd Value]]) -> 66600 | K46: 3.7 | L46: 18000 | M46: 15.06.26 | N46: 30.06.26 | O46: =IFERROR(_xlfn.XLOOKUP(C46, Data!$A$2:$A$236, Data!$C$2:$C$236), "") -> Mr. Reza Sir
A47: =A48+1 -> 175 | B47: 21133/26 | C47: MAMUN KNITWEAR LTD. | D47: UCBL BANGSHAL BRANCH | E47: 1007 2604 01269 | F47: 14.05.26 | G47: 46162 | H47: 44400 | J47: =SUM(Table14[[#This Row],[LC Value]:[Amd Value]]) -> 44400 | K47: 3.7 | L47: 12000 | M47: 15.06.26 | N47: 30.06.26 | O47: =IFERROR(_xlfn.XLOOKUP(C47, Data!$A$2:$A$236, Data!$C$2:$C$236), "") -> Mr. Reza Sir
A48: =A49+1 -> 174 | B48: 21136/26 | C48: MAMUN KNITWEAR LTD. | D48: UCBL BANGSHAL BRANCH | E48: 1007 2604 01263 | F48: 14.05.26 | G48: 46162 | H48: 55500 | J48: =SUM(Table14[[#This Row],[LC Value]:[Amd Value]]) -> 55500 | K48: 3.7 | L48: 15000 | M48: 15.06.26 | N48: 30.06.26 | O48: =IFERROR(_xlfn.XLOOKUP(C48, Data!$A$2:$A$236, Data!$C$2:$C$236), "") -> Mr. Reza Sir
A49: =A50+1 -> 173 | B49: 21144/26 | C49: NZ FABRICS LTD. | D49: CITY BANK PLC TSD. GULSHAN BRANCH. | E49: 0751 2603 00831 | F49: 14.05.26 | G49: 46162 | H49: 10392.5 | J49: =SUM(Table14[[#This Row],[LC Value]:[Amd Value]]) -> 10392.5 | K49: 3.8 | L49: 2750 | M49: 05.07.26 | N49: 29.06.26 | O49: =IFERROR(_xlfn.XLOOKUP(C49, Data!$A$2:$A$236, Data!$C$2:$C$236), "") -> MD. Sir
A50: =A51+1 -> 172 | B50: 21145/26 | C50: NZ DENIM LTD. | D50: BRAC BANK T.O. TEJGAON BRANCH. | E50: 3085 2603 00759 | F50: 13.05.26 | G50: 46162 | H50: 66080 | J50: =SUM(Table14[[#This Row],[LC Value]:[Amd Value]]) -> 66080 | K50: 2.95 | L50: 22400 | M50: 05.07.26 | N50: 20.07.26 | O50: =IFERROR(_xlfn.XLOOKUP(C50, Data!$A$2:$A$236, Data!$C$2:$C$236), "") -> MD. Sir
A51: =A52+1 -> 171 | B51: 21141/26 | C51: NZ DENIM LTD. | D51: BRAC BANK T.O. TEJGAON BRANCH. | E51: 3085 2603 00749 | F51: 13.05.26 | G51: 46160 | H51: 25070 | J51: =SUM(Table14[[#This Row],[LC Value]:[Amd Value]]) -> 25070 | K51: 4.15 | L51: 6100 | M51: 05.07.26 | N51: 20.07.26 | O51: =IFERROR(_xlfn.XLOOKUP(C51, Data!$A$2:$A$236, Data!$C$2:$C$236), "") -> MD. Sir
A52: =A53+1 -> 170 | B52: 21142/26 | C52: NZ DENIM LTD. | D52: BRAC BANK T.O. TEJGAON BRANCH. | E52: 3085 2603 00750 | F52: 13.05.26 | G52: 46160 | H52: 19932.5 | J52: =SUM(Table14[[#This Row],[LC Value]:[Amd Value]]) -> 19932.5 | K52: 3.9 | L52: 5150 | M52: 05.07.26 | N52: 20.07.26 | O52: =IFERROR(_xlfn.XLOOKUP(C52, Data!$A$2:$A$236, Data!$C$2:$C$236), "") -> MD. Sir
A53: =A54+1 -> 169 | B53: 21132/26 | C53: NZ FABRICS LTD. | D53: CITY BANK PLC TSD. GULSHAN BRANCH. | E53: 0751 2603 00807 | F53: 11.05.26 | G53: 46158 | H53: 24232.5 | J53: =SUM(Table14[[#This Row],[LC Value]:[Amd Value]]) -> 24232.5 | K53: 4.2 | L53: 5650 | M53: 05.07.26 | N53: 20.07.26 | O53: =IFERROR(_xlfn.XLOOKUP(C53, Data!$A$2:$A$236, Data!$C$2:$C$236), "") -> MD. Sir
A54: =A55+1 -> 168 | B54: 21130/26 21131/26 | C54: NZ DENIM LTD. | D54: CITY BANK PLC TSD. GULSHAN BRANCH. | E54: 0751 2603 00805 | F54: 11.05.26 | G54: 46158 | H54: =24415+13035 -> 37450 | J54: =SUM(Table14[[#This Row],[LC Value]:[Amd Value]]) -> 37450 | K54: 1.9 | L54: 12850 | M54: 05.07.26 | N54: 20.07.26 | O54: =IFERROR(_xlfn.XLOOKUP(C54, Data!$A$2:$A$236, Data!$C$2:$C$236), "") -> MD. Sir
...

Sheet NZDY
A1: Sl No | B1: PI NO | C1: Applicant Name | D1: Issuing Bank | E1: LC Number | F1: LC Date | G1: LC Rev Date | H1: LC Value | I1: Amd Value | J1: Total | K1: Unit Price | L1: Quantity | M1: Shipment Date | N1: Expiry Date | O1: Marketing Person
A2: 39 | B2: 0073/26 | C2: NZ FABRICS LTD. | D2: BRAC BANK T.O. TEJGAON BRANCH. | E2: 3085 2603 00919 | F2: 18.06.26 | G2: 46193 | H2: 24050 | J2: =SUM(Table145[[#This Row],[LC Value]:[Amd Value]]) -> 24050 | K2: 13 | L2: 1850 | M2: 25.07.26 | N2: 09.08.26 | O2: =IFERROR(_xlfn.XLOOKUP(C2, Data!$A$2:$A$236, Data!$C$2:$C$236), "") -> MD. Sir
A3: 38 | B3: 0074/26 | C3: NZ FABRICS LTD. | D3: CITY BANK PLC TSD. GULSHAN BRANCH. | E3: 0751 2603 00967 | F3: 18.06.26 | G3: 46193 | H3: 8000 | J3: =SUM(Table145[[#This Row],[LC Value]:[Amd Value]]) -> 8000 | K3: 16 | L3: 500 | M3: 25.07.26 | N3: 09.08.26 | O3: =IFERROR(_xlfn.XLOOKUP(C3, Data!$A$2:$A$236, Data!$C$2:$C$236), "") -> MD. Sir
A4: 37 | B4: 0069/26 | C4: ACS TEXTILES (BANGLADESH) LTD. | D4: SOUTHEAST BANK LTD. PRINCIPAL BRANCH | E4: 1335 2603 00226 | F4: 16.06.26 | G4: 46194 | H4: 48820 | J4: =SUM(Table145[[#This Row],[LC Value]:[Amd Value]]) -> 48820 | K4: 19.7 | L4: 2000 | M4: 05.08.26 | N4: 25.08.26 | O4: =IFERROR(_xlfn.XLOOKUP(C4, Data!$A$2:$A$236, Data!$C$2:$C$236), "") -> Director Sir
A5: 36 | B5: 0071/26 | C5: NZ FABRICS LTD. | D5: CITY BANK PLC TSD. GULSHAN BRANCH. | E5: 0751 2603 00938 | F5: 11.06.26 | G5: 46191 | H5: 12150 | J5: =SUM(Table145[[#This Row],[LC Value]:[Amd Value]]) -> 12150 | K5: 13.5 | L5: 900 | M5: 24.06.26 | N5: 09.07.26 | O5: =IFERROR(_xlfn.XLOOKUP(C5, Data!$A$2:$A$236, Data!$C$2:$C$236), "") -> MD. Sir
A6: 35 | B6: 0070/26 | C6: NZ DENIM LTD. | D6: CITY BANK PLC TSD. GULSHAN BRANCH. | E6: 0751 2603 00935 | F6: 10.06.26 | G6: 46191 | H6: 9800 | J6: =SUM(Table145[[#This Row],[LC Value]:[Amd Value]]) -> 9800 | K6: 14 | L6: 700 | M6: 24.06.26 | N6: 09.07.26 | O6: =IFERROR(_xlfn.XLOOKUP(C6, Data!$A$2:$A$236, Data!$C$2:$C$236), "") -> MD. Sir
A7: 34 | B7: 0066/26 | C7: NZ FABRICS LTD. | D7: CITY BANK PLC TSD. GULSHAN BRANCH. | E7: 0751 2603 00917 | F7: 01.06.26 | G7: 46181 | H7: 125550 | J7: =SUM(Table145[[#This Row],[LC Value]:[Amd Value]]) -> 125550 | K7: 13.5 | L7: 9300 | M7: 10.07.26 | N7: 25.07.26 | O7: =IFERROR(_xlfn.XLOOKUP(C7, Data!$A$2:$A$236, Data!$C$2:$C$236), "") -> MD. Sir
A8: 33 | B8: 0065/26 | C8: NZ FABRICS LTD. | D8: BRAC BANK T.O. TEJGAON BRANCH. | E8: 3085 2603 00827 | F8: 23.05.26 | G8: 46181 | H8: 8000 | J8: =SUM(Table145[[#This Row],[LC Value]:[Amd Value]]) -> 8000 | K8: 20 | L8: 400 | M8: 10.07.26 | N8: 25.07.26 | O8: =IFERROR(_xlfn.XLOOKUP(C8, Data!$A$2:$A$236, Data!$C$2:$C$236), "") -> MD. Sir
A9: 32 | B9: 0063/26 | C9: NZ FABRICS LTD. | D9: CITY BANK PLC TSD. GULSHAN BRANCH. | E9: 0751 2603 00903 | F9: 23.05.26 | G9: 46181 | H9: 25200 | J9: =SUM(Table145[[#This Row],[LC Value]:[Amd Value]]) -> 25200 | K9: 14 | L9: 1800 | M9: 10.07.26 | N9: 25.07.26 | O9: =IFERROR(_xlfn.XLOOKUP(C9, Data!$A$2:$A$236, Data!$C$2:$C$236), "") -> MD. Sir
A10: 31 | B10: 0060/26 | C10: NZ FABRICS LTD. | D10: CITY BANK PLC TSD. GULSHAN BRANCH. | E10: 0751 2603 00830 | F10: 13.05.26 | G10: 46162 | H10: 14950 | J10: =SUM(Table145[[#This Row],[LC Value]:[Amd Value]]) -> 14950 | K10: 13 | L10: 1150 | M10: 10.07.26 | N10: 25.07.26 | O10: =IFERROR(_xlfn.XLOOKUP(C10, Data!$A$2:$A$236, Data!$C$2:$C$236), "") -> MD. Sir
A11: 30 | B11: 0059/26 | C11: NZ DENIM LTD. | D11: BRAC BANK T.O. TEJGAON BRANCH. | E11: 3085 2603 00752 | F11: 13.05.26 | G11: 46161 | H11: 13300 | J11: =SUM(Table145[[#This Row],[LC Value]:[Amd Value]]) -> 13300 | K11: 14 | L11: 950 | M11: 10.07.26 | N11: 25.07.26 | O11: =IFERROR(_xlfn.XLOOKUP(C11, Data!$A$2:$A$236, Data!$C$2:$C$236), "") -> MD. Sir
A12: 29 | B12: 0047/26 | C12: ACS TEXTILES (BANGLADESH) LTD. | D12: SOUTHEAST BANK LTD. PRINCIPAL BRANCH | E12: 1335 2604 01427 | F12: 27.04.26 | G12: 46147 | H12: 91000 | J12: =SUM(Table145[[#This Row],[LC Value]:[Amd Value]]) -> 91000 | K12: 19 | L12: 4800 | M12: 23.06.26 | N12: 08.07.26 | O12: =IFERROR(_xlfn.XLOOKUP(C12, Data!$A$2:$A$236, Data!$C$2:$C$236), "") -> Director Sir
A13: 28 | B13: 0055/26 | C13: NZ FABRICS LTD. | D13: CITY BANK PLC TSD. GULSHAN BRANCH. | E13: 0751 2603 00738 | F13: 29.04.26 | G13: 46147 | H13: 16800 | J13: =SUM(Table145[[#This Row],[LC Value]:[Amd Value]]) -> 16800 | K13: 16 | L13: 1050 | M13: 27.04.26 | N13: 12.05.26 | O13: =IFERROR(_xlfn.XLOOKUP(C13, Data!$A$2:$A$236, Data!$C$2:$C$236), "") -> MD. Sir
... A17: 24 | B17: 0045/26 | C17: AKIJ TEXTILE MILLS LTD. | D17: ISLAMI BANK PLC. HEAD OFFICE COMPLEX BRANCH | E17: 0887 2604 0143 | F17: 07.04.26 | G17: 46131 | H17: 17000 | J17: =SUM(Table145[[#This Row],[LC Value]:[Amd Value]]) -> 17000 | K17: 17 | L17: 1000 | M17: 13.04.26 | N17: 23.04.26 | O17: =IFERROR(_xlfn.XLOOKUP(C17, Data!$A$2:$A$236, Data!$C$2:$C$236), "") -> Mr. Lipu Sir
A18: 23 | B18: 0043/26 | C18: NZ DENIM LTD. | D18: CITY BANK PLC TSD. GULSHAN BRANCH. | E18: 0751 2603 00544 | F18: 31.03.26 | G18: 46119 | H18: 9100 | I18: 16100 | J18: =SUM(Table145[[#This Row],[LC Value]:[Amd Value]]) -> 25200 | K18: 14 | L18: 650 | M18: 13.04.26 | N18: 23.04.26 | O18: =IFERROR(_xlfn.XLOOKUP(C18, Data!$A$2:$A$236, Data!$C$2:$C$236), "") -> MD. Sir
A19: 22 | B19: 0035/26 | C19: HOORAIN HTF LTD. | D19: AGRANI BANK PLC PRINCIPAL BRANCH | E19: 0001 2604 00444 | F19: 29.03.26 | G19: 46114 | H19: 75075 | J19: =SUM(Table145[[#This Row],[LC Value]:[Amd Value]]) -> 75075 | K19: 16.5 | L19: 4550 | M19: 13.04.26 | N19: 23.04.26 | O19: =IFERROR(_xlfn.XLOOKUP(C19, Data!$A$2:$A$236, Data!$C$2:$C$236), "") -> Mr. Lipu Sir
A20: 21 | B20: 0036/26 | C20: HOORAIN HTF LTD. | D20: AGRANI BANK PLC PRINCIPAL BRANCH | E20: 0001 2604 00445 | F20: 29.03.26 | G20: 46114 | H20: 72600 | J20: =SUM(Table145[[#This Row],[LC Value]:[Amd Value]]) -> 72600 | K20: 16.5 | L20: 4400 | M20: 13.04.26 | N20: 23.04.26 | O20: =IFERROR(_xlfn.XLOOKUP(C20, Data!$A$2:$A$236, Data!$C$2:$C$236), "") -> Mr. Lipu Sir
A21: 20 | B21: 0033/26 | C21: HOORAIN HTF LTD. | D21: AGRANI BANK PLC PRINCIPAL BRANCH | E21: 0001 2604 00341 | F21: 10.03.26 | G21: 46097 | H21: 77500 | J21: =SUM(Table145[[#This Row],[LC Value]:[Amd Value]]) -> 77500 | K21: 16.5 | L21: 4700 | M21: 19.04.26 | N21: 29.04.26 | O21: =IFERROR(_xlfn.XLOOKUP(C21, Data!$A$2:$A$236, Data!$C$2:$C$236), "") -> Mr. Lipu Sir
A22: 19 | B22: 0034/26 | C22: HOORAIN HTF LTD. | D22: AGRANI BANK PLC PRINCIPAL BRANCH | E22: 0001 2604 00345 | F22: 10.03.26 | G22: 46097 | H22: 75900 | J22: =SUM(Table145[[#This Row],[LC Value]:[Amd Value]]) -> 75900 | K22: 16.5 | L22: 4600 | M22: 29.03.26 | N22: 23.04.26 | O22: =IFERROR(_xlfn.XLOOKUP(C22, Data!$A$2:$A$236, Data!$C$2:$C$236), "") -> Mr. Lipu Sir
A23: 18 | B23: 0031/26 | C23: HOORAIN HTF LTD. | D23: AGRANI BANK PLC PRINCIPAL BRANCH | E23: 0001 2604 00343 | F23: 10.03.26 | G23: 46097 | H23: 79200 | J23: =SUM(Table145[[#This Row],[LC Value]:[Amd Value]]) -> 79200 | K23: 16.5 | L23: 4800 | M23: 29.03.26 | N23: 08.04.26 | O23: =IFERROR(_xlfn.XLOOKUP(C23, Data!$A$2:$A$236, Data!$C$2:$C$236), "") -> Mr. Lipu Sir
A24: 17 | B24: 0038/26 | C24: NZ FABRICS LTD. | D24: CITY BANK PLC TSD. GULSHAN BRANCH. | E24: 0751 2603 00439 | F24: 19.02.26 | G24: 46097 | H24: 38150 | J24: =SUM(Table145[[#This Row],[LC Value]:[Amd Value]]) -> 38150 | K24: 12 | L24: 3150 | M24: 20.04.26 | N24: 05.05.26 | O24: =IFERROR(_xlfn.XLOOKUP(C24, Data!$A$2:$A$236, Data!$C$2:$C$236), "") -> MD. Sir
A25: 16 | B25: 0029/26 | C25: ACS TEXTILES (BANGLADESH) LTD. | D25: MIDLAND BANK PLC GULSHAN BRANCH | E25: 3355 2604 00120 | F25: 19.02.26 | G25: 46085 | H25: 69125 | J25: =SUM(Table145[[#This Row],[LC Value]:[Amd Value]]) -> 69125 | K25: 17.5 | L25: 3950 | M25: 20.04.26 | N25: 05.05.26 | O25: =IFERROR(_xlfn.XLOOKUP(C25, Data!$A$2:$A$236, Data!$C$2:$C$236), "") -> Director Sir
A26: 15 | B26: 0037/26 | C26: NZ DENIM LTD. | D26: BRAC BANK T.O. TEJGAON BRANCH. | E26: 3085 2603 00364 | F26: 02.03.26 | G26: 46090 | H26: 36400 | J26: =SUM(Table145[[#This Row],[LC Value]:[Amd Value]]) -> 36400 | K26: 14 | L26: 2600 | M26: 26.03.26 | N26: 10.04.26 | O26: =IFERROR(_xlfn.XLOOKUP(C26, Data!$A$2:$A$236, Data!$C$2:$C$236), "") -> MD. Sir
A27: 14 | B27: 0028/26 | C27: NZ FABRICS LTD. | D27: EBL TO GULSHAN AVENUE | E27: 1475 2603 00342 | F27: 10.02.26 | G27: 46072 | H27: 8800 | J27: =SUM(Table145[[#This Row],[LC Value]:[Amd Value]]) -> 8800 | K27: 16 | L27: 550 | M27: 09.03.26 | N27: 24.03.26 | O27: =IFERROR(_xlfn.XLOOKUP(C27, Data!$A$2:$A$236, Data!$C$2:$C$236), "") -> MD. Sir
A28: 13 | B28: 0026/26 | C28: NZ FABRICS LTD. | D28: EBL TO GULSHAN AVENUE | E28: 1475 2603 00271 | F28: 02.02.26 | G28: 46070 | H28: 53600 | J28: =SUM(Table145[[#This Row],[LC Value]:[Amd Value]]) -> 53600 | K28: 16 | L28: 3350 | M28: 27.02.26 | N28: 14.03.26 | O28: =IFERROR(_xlfn.XLOOKUP(C28, Data!$A$2:$A$236, Data!$C$2:$C$236), "") -> MD. Sir
A29: 12 | B29: 0025/26 | C29: NZ FABRICS LTD. | D29: CITY BANK PLC TSD. GULSHAN BRANCH. | E29: 0751 2603 00235 | F29: 02.02.26 | G29: 46062 | H29: 26000 | J29: =SUM(Table145[[#This Row],[LC Value]:[Amd Value]]) -> 26000 | K29: 13 | L29: 2000 | M29: 27.02.26 | N29: 14.03.26 | O29: =IFERROR(_xlfn.XLOOKUP(C29, Data!$A$2:$A$236, Data!$C$2:$C$236), "") -> MD. Sir
A30: 11 | B30: 0023/26 | C30: NZ DENIM LTD. | D30: SHAHJALAL ISLAMI BANK LTD. KAWRAN BAZAR BRANCH | E30: 2970 2603 00025 | F30: 29.01.26 | G30: 46056 | H30: 10200 | J30: =SUM(Table145[[#This Row],[LC Value]:[Amd Value]]) -> 10200 | K30: 12 | L30: 850 | M30: 13.03.26 | N30: 28.03.26 | O30: =IFERROR(_xlfn.XLOOKUP(C30, Data!$A$2:$A$236, Data!$C$2:$C$236), "") -> MD. Sir
... A40: 01 | B40: 0002/25 | C40: NZ FABRICS LTD. | D40: EBL TRADE OPERATIONS GULSHAN BRANCH. | E40: 1475 2603 00014 | F40: 04.01.26 | G40: 46035 | H40: 32250 | J40: =SUM(Table145[[#This Row],[LC Value]:[Amd Value]]) -> 32250 | K40: 15 | L40: 2150 | M40: 04.02.26 | N40: 19.02.26 | O40: =IFERROR(_xlfn.XLOOKUP(C40, Data!$A$2:$A$236, Data!$C$2:$C$236), "") -> MD. Sir

Sheet Data
A1: Applicant Name | B1: Bank | C1: Marketing Person | E1: Bank Keyword | F1: LC Prefix
A2: ABF KNIT WEAR LTD. | B2: JANATA BANK PLC. NARAYANGANJ BRANCH | C2: Mr. Lipu Sir | E2: BRAC BANK | F2: 3085
A3: ABLOOM DESIGN LTD. | B3: PREMIER BANK LTD. NARAYANGONJ BRANCH | C3: Mr. Amran Sir | E3: DBBL | F3: 1680
A4: ABONI TEXTILES LTD. | B4: HSBC TEJGAON BRANCH | C4: Mr. Reza Sir | E4: CITY BANK | F4: 0751
A5: ACS TEXTILES (BANGLADESH) LTD. | B5: SOUTHEAST BANK LTD. PRINCIPAL BRANCH | C5: Director Sir | E5: EBL | F5: 1475
A6: ACS TOWELS LTD. | B6: SOUTHEAST BANK LTD. PRINCIPAL BRANCH | C6: Director Sir | E6: SHAHJALAL ISLAMI BANK | F6: 2970
A7: ACTIVE COMPOSITE MILLS LTD. | B7: MERCANTILE BANK PLC. BANANI BRANCH | C7: Mr. Lipu Sir | E7: PREMIER BANK | F7: 2155
A8: AFIYA KNITWEAR LTD. | B8: SOCIAL ISLAMI BANK PLC. UTTARA BRANCH | C8: Mr. Lipu Sir | E8: UCBL | F8: 1021
A9: AKIJ TEXTILE MILLS LTD. | B9: COMMERCIAL BANK OF CEYLON PLC GULSHAN BRANCH | C9: Mr. Lipu Sir | E9: DHAKA BANK | F9: 1416
A10: ALIM KNIT (BD) LTD. | B10: SHAHJALAL ISLAMI BANK PLC UTTARA BRANCH | C10: Director Sir | E10: AL-ARAFAH ISLAMI BANK | F10: 1088
A11: ALLIANCE KNIT COMPOSITE LTD. | B11: UCBL FOREIGN EXCHANGE BRANCH | C11: Mr. Reza Sir | E11: EXIM BANK | F11: 1952
A12: APEX FASHION WEAR LTD. | B12: BRAC BANK T.O. TEJGAON BRANCH. | C12: Mr. Sohel Sir | E12: ONE BANK | F12: 1877
A13: APEX SPINNING & KNITING MILLS LTD. | B13: HSBC TEJGAON BRANCH | C13: Mr. Sohel Sir | E13: ISLAMI BANK | F13: 0887
A14: APEX TEXTILE PRINTING MILLS LTD. | B14: HSBC TEJGAON BRANCH | C14: Mr. Sohel Sir | E14: STANDARD CHARTERED | F14: 4110
A15: APPARELS VILLAGE LTD. | B15: ONE BANK PLC PRINCIPAL BRANCH | C15: Director Sir | E15: MODHUMOTI BANK | F15: 3505
A16: APS APPARELS LTD. | B16: UCBL TSC MOTIJHEEL BRANCH | C16: Mr. Reza Sir | E16: AGRANI BANK | F16: 0033
A17: AR TEX COMPOSITE LTD. | B17: DBBL CTS-NARAYANGANJ BRANCH | C17: Mr. Sohel Sir | E17: IFIC BANK | F17: 0796
A18: ARGON DENIMS LTD. | B18: ONE BANK PLC MOGHBAZAR BRANCH | C18: Mr. Lipu Sir | E18: PUBALI BANK | F18: 0201
A19: ARKAY KNIT DYEING MILLS LTD. | B19: MUTUAL TRUST BANK LTD. MIST MOTIJHEEL BRANCH | C19: Mr. Lipu Sir | E19: BANK ASIA | F19: 2090
A20: AXIS KNITWEARS LTD. | B20: DBBL CTS-TEJGAON BRANCH | C20: Mr. Amran Sir | E20: HSBC | F20: DPCB
A21: BARNALI TEXTILE AND PRINTING IND. (PVT) LTD. | B21: JAMUNA BANK N.GONJ BRANCH. | C21: Mr. Wadud Sir | E21: NCC BANK | F21: 1616
A22: BEA-CON KNITWEAR LTD. | B22: UCBL TSC DILKUSHA BRANCH | C22: Mr. Lipu Sir | E22: SOCIAL ISLAMI BANK | F22: 1216
A23: BLUE PLANET FASHION WEAR LTD. | B23: ISLAMI BANK BANGLADESH PLC VIP ROAD BRANCH | C23: Mr. Lipu Sir | E23: MERCANTILE BANK | F23: 1747
A24: BLUE PLANET KNITWEAR LTD. | B24: MODHUMOTI BANK PLC UTTARA BRANCH | C24: Mr. Lipu Sir | E24: JAMUNA BANK | F24: 3054
A25: BONIAN KNIT FASHION LTD. | B25: SHAHJALAL ISLAMI BANK PLC. DHKA MAIN BRANCH. DILKUSHA | C25: Mr. Reza Sir | E25: TRUST BANK | F25: 2361
A26: BOTTOMS GALLERY (PVT) LTD. | B26: AGRANI BANK PLC GULSHAN CORPORATE BRANCH | C26: Mr. Amran Sir | E26: MTB | F26: 2228
A27: BRAVO DESIGN LTD. | B27: AGRANI BANK LTD. SHEEATON HOTEL BRANCH | C27: Mr. Reza Sir | E27: JANATA BANK | F27: 0108
A28: CA KNITWEAR LTD. | B28: UNITED COMMERCIAL BANK PLC. GULSHAN BRANCH | C28: Mr. Reza Sir | E28: EBL | F28: 1471
A29: CHAITY COMPOSITE LTD. | B29: SOUTHEAST BANK PLC. GULSHAN BRANCH | C29: Mr. Wadud Sir | E29: STANDARD BANK | F29: 1822
A30: CHORKA TEXTILE LTD. | B30: ISLAMI BANK PLC. HEAD OFFICE COMPLEX BRANCH | C30: Mr. Lipu Sir | E30: SOUTHEAST BANK | F30: 1346
A31: COLOUR AND CO.LTD | B31: UCBL UTTARA BRANCH | C31: Mr. Lipu Sir | E31: PREMIER BANK | F31: 2152
A32: COMFIT COMPOSITE KNIT LTD. | B32: HSBC TEJGAON BRANCH | C32: Mr. Reza Sir | E32: UNITED COMMERCIAL BANK | F32: 1021
A33: COMPTEX BANGLADESH LTD. | B33: BANK ASIA LTD BANANI BRANCH | C33: Mr. Reza Sir | E33: COMMERCIAL BANK OF CEYLON PLC | F33: 2655
A34: CONFIDENCE KNITTING IND. LTD. | B34: MASHREQ BANK PSC. NEW YORK | C34: Mr. Lipu Sir | E34: SHAHJALAL ISLAMI BANK | F34: 2969
A35: CONFIDENCE KNITWEAR LTD. | B35: ISLAMI BANK BANGLADESH PLC. UTTARA BRANCH | C35: Mr. Lipu Sir | E35: HSBC | F35: BBCD
A36: COTTON CLUB (BD) LTD. | B36: UNITED COMMERCIAL BANK PLC. NIKUNJA BRANCH | C36: Director Sir | E36: SHAHJALAL ISLAMI BANK | F36: 2979
A37: DICA TEX LTD. | B37: TRUST BANK UTTARA BRANCH | C37: Mr. Lipu Sir | E37: SOUTHEAST BANK | F37: 1335
A38: DIP KNITWEAR LTD. | B38: SJIBL BANANI BRANCH | C38: Mr. Lipu Sir | E38: AGRANI BANK | F38: 0006
A39: DIVINE FABRICS LTD. | B39: DHAKA BANK PLC.. CPC-TO. PURANA PALTAN LANE | C39: Mr. Reza Sir | E39: PREMIER BANK | F39: 2162
A40: DIVING SPINNING MILLS LTD. | B40: DHAKA BANK PLC. TO GULSHAN BRANCH | C40: Director Sir | E40: DBBL | F40: 1690
...
